Workbook

Sheet Microsoft Stock Price History (
A1: Date | B1: Price | C1: Open | D1: High | E1: Low | F1: Vol. | G1: Change %
A2: 04/25/2025 | B2: 39185 | C2: 38700 | D2: 39216 | E2: 38460 | F2: 18.97M | G2: 1.17
A3: 04/24/2025 | B3: 38730 | C3: 37570 | D3: 38845 | E3: 37519 | F3: 22.23M | G3: 3.45
A4: 04/23/2025 | B4: 37439 | C4: 37606 | D4: 38039 | E4: 37302 | F4: 20.55M | G4: 2.06
A5: 04/22/2025 | B5: 36682 | C5: 36338 | D5: 36777 | E5: 35986 | F5: 19.48M | G5: 2.14
A6: 04/21/2025 | B6: 35912 | C6: 36282 | D6: 36448 | E6: 35567 | F6: 20.81M | G6: -2.35
A7: 04/17/2025 | B7: 36778 | C7: 37374 | D7: 37432 | E7: 36689 | F7: 21.12M | G7: -1.03
A8: 04/16/2025 | B8: 37161 | C8: 38067 | D8: 38161 | E8: 36800 | F8: 21.97M | G8: -3.66
A9: 04/15/2025 | B9: 38573 | C9: 38851 | D9: 39189 | E9: 38416 | F9: 17.20M | G9: -0.54
A10: 04/14/2025 | B10: 38781 | C10: 39322 | D10: 39465 | E10: 38421 | F10: 19.25M | G10: -0.16
A11: 04/11/2025 | B11: 38845 | C11: 38064 | D11: 39005 | E11: 37889 | F11: 23.84M | G11: 1.86
A12: 04/10/2025 | B12: 38135 | C12: 38206 | D12: 38390 | E12: 36780 | F12: 38.02M | G12: -2.34
A13: 04/09/2025 | B13: 39049 | C13: 35354 | D13: 39323 | E13: 35310 | F13: 50.20M | G13: 10.13
... A2596: 01/02/2015 | B2596: 4676 | C2596: 4666 | D2596: 4742 | E2596: 4654 | F2596: 27.91M | G2596: 0.67

Sheet Alphabet C Stock Price History 
A1: Date | B1: Price | C1: Open | D1: High | E1: Low | F1: Vol. | G1: Change %
A2: 04/25/2025 | B2: 16385 | C2: 16710 | D2: 16824 | E2: 16300 | F2: 35.15M | G2: 1.47
A3: 04/24/2025 | B3: 16147 | C3: 15852 | D3: 16171 | E3: 15809 | F3: 30.79M | G3: 2.38
A4: 04/23/2025 | B4: 15772 | C4: 15791 | D4: 16002 | E4: 15635 | F4: 18.58M | G4: 2.48
A5: 04/22/2025 | B5: 15390 | C5: 15107 | D5: 15461 | E5: 15087 | F5: 15.91M | G5: 2.7
A6: 04/21/2025 | B6: 14986 | C6: 15096 | D6: 15106 | E6: 14840 | F6: 16.15M | G6: -2.28
A7: 04/17/2025 | B7: 15336 | C7: 15661 | D7: 15707 | E7: 15090 | F7: 19.51M | G7: -1.38
A8: 04/16/2025 | B8: 15550 | C8: 15547 | D8: 15818 | E8: 15391 | F8: 16.92M | G8: -2
A9: 04/15/2025 | B9: 15868 | C9: 16157 | D9: 16205 | E9: 15765 | F9: 15.69M | G9: -1.73
A10: 04/14/2025 | B10: 16147 | C10: 16231 | D10: 16403 | E10: 15992 | F10: 18.26M | G10: 1.3
A11: 04/11/2025 | B11: 15940 | C11: 15559 | D11: 15986 | E11: 15559 | F11: 22.58M | G11: 2.59
A12: 04/10/2025 | B12: 15537 | C12: 15876 | D12: 16003 | E12: 15220 | F12: 35.27M | G12: -3.53
A13: 04/09/2025 | B13: 16106 | C13: 14633 | D13: 16187 | E13: 14581 | F13: 46.48M | G13: 9.88
... A2595: 01/02/2015 | B2595: 2617 | C2595: 2638 | D2595: 2649 | E2595: 2613 | F2595: 29.01M | G2595: -0.3

Sheet Tesla Stock Price History
A1: Date | B1: Price | C1: Open | D1: High | E1: Low | F1: Vol. | G1: Change %
A2: 04/25/2025 | B2: 28495 | C2: 26169 | D2: 28685 | E2: 25963 | F2: 167.56M | G2: 9.8
A3: 04/24/2025 | B3: 25951 | C3: 25050 | D3: 25954 | E3: 24920 | F3: 94.46M | G3: 3.5
A4: 04/23/2025 | B4: 25074 | C4: 25486 | D4: 25945 | E4: 24443 | F4: 150.38M | G4: 5.37
A5: 04/22/2025 | B5: 23797 | C5: 23096 | D5: 24279 | E5: 22985 | F5: 120.86M | G5: 4.6
A6: 04/21/2025 | B6: 22750 | C6: 23026 | D6: 23221 | E6: 22279 | F6: 97.77M | G6: -5.75
A7: 04/17/2025 | B7: 24137 | C7: 24347 | D7: 24434 | E7: 23768 | F7: 83.40M | G7: -0.07
A8: 04/16/2025 | B8: 24155 | C8: 24761 | D8: 25197 | E8: 23389 | F8: 112.38M | G8: -4.94
A9: 04/15/2025 | B9: 25411 | C9: 24991 | D9: 25875 | E9: 24754 | F9: 79.59M | G9: 0.7
A10: 04/14/2025 | B10: 25235 | C10: 25836 | D10: 26180 | E10: 24593 | F10: 100.14M | G10: 0.02
A11: 04/11/2025 | B11: 25231 | C11: 25184 | D11: 25774 | E11: 24136 | F11: 128.95M | G11: -0.04
A12: 04/10/2025 | B12: 25240 | C12: 26000 | D12: 26249 | E12: 23933 | F12: 181.72M | G12: -7.27
A13: 04/09/2025 | B13: 27220 | C13: 22469 | D13: 27469 | E13: 22388 | F13: 219.43M | G13: 22.69
... A2595: 01/02/2015 | B2595: 1462 | C2595: 1486 | D2595: 1488 | E2595: 1422 | F2595: 71.47M | G2595: -1.42

Sheet Louis Vuitton Stock Price Histo
A1: Date | B1: Price | C1: Open | D1: High | E1: Low | F1: Vol. | G1: Change %
A2: 04/25/2025 | B2: 49880 | C2: 50400 | D2: 50650 | E2: 49725 | F2: 561.90K | G2: -0.18
A3: 04/24/2025 | B3: 49970 | C3: 49025 | D3: 50180 | E3: 48605 | F3: 605.88K | G3: -0.12
A4: 04/23/2025 | B4: 50030 | C4: 49235 | D4: 51510 | E4: 49185 | F4: 844.26K | G4: 2.67
A5: 04/22/2025 | B5: 48730 | C5: 48945 | D5: 48980 | E5: 47125 | F5: 809.14K | G5: 0.35
A6: 04/17/2025 | B6: 48560 | C6: 48210 | D6: 49330 | E6: 48095 | F6: 902.70K | G6: 0.08
A7: 04/16/2025 | B7: 48520 | C7: 48300 | D7: 48900 | E7: 47930 | F7: 1.09M | G7: -0.71
A8: 04/15/2025 | B8: 48865 | C8: 50100 | D8: 50240 | E8: 48475 | F8: 1.69M | G8: -7.82
A9: 04/14/2025 | B9: 53010 | C9: 53500 | D9: 53600 | E9: 52460 | F9: 593.48K | G9: 1.09
A10: 04/11/2025 | B10: 52440 | C10: 52820 | D10: 53200 | E10: 51280 | F10: 574.90K | G10: 0.04
A11: 04/10/2025 | B11: 52420 | C11: 54740 | D11: 54800 | E11: 52040 | F11: 912.11K | G11: 5.18
A12: 04/09/2025 | B12: 49840 | C12: 49670 | D12: 51060 | E12: 49415 | F12: 984.16K | G12: -4.12
A13: 04/08/2025 | B13: 51980 | C13: 51740 | D13: 52680 | E13: 50130 | F13: 902.07K | G13: 2.4
... A155: 09/17/2024 | B155: 60770 | C155: 60820 | D155: 61190 | E155: 60350 | F155: 519.69K | G155: 0.68
A156: 09/16/2024 | B156: 60360 | C156: 60830 | D156: 61350 | E156: 60320 | G156: -0.74
A157: 09/13/2024 | B157: 60810 | C157: 60600 | D157: 61490 | E157: 60600 | F157: 545.50K | G157: 0.21
A158: 09/12/2024 | B158: 60680 | C158: 61670 | D158: 61750 | E158: 60300 | F158: 438.72K | G158: -0.03
A159: 09/11/2024 | B159: 60700 | C159: 61240 | D159: 61930 | E159: 60240 | F159: 453.88K | G159: -0.88
A160: 09/10/2024 | B160: 61240 | C160: 61400 | D160: 62080 | E160: 61060 | F160: 324.13K | G160: -0.62
A161: 09/09/2024 | B161: 61620 | C161: 61200 | D161: 62020 | E161: 60850 | F161: 402.86K | G161: 0.69
A162: 09/06/2024 | B162: 61200 | C162: 61900 | D162: 62220 | E162: 61200 | F162: 546.37K | G162: -1.16
A163: 09/05/2024 | B163: 61920 | C163: 64080 | D163: 64090 | E163: 61740 | F163: 745.29K | G163: -3.64
A164: 09/04/2024 | B164: 64260 | C164: 65260 | D164: 65980 | E164: 64130 | F164: 577.52K | G164: -4.22
A165: 09/03/2024 | B165: 67090 | C165: 67750 | D165: 68150 | E165: 67000 | F165: 250.24K | G165: -0.34
A166: 09/02/2024 | B166: 67320 | C166: 67090 | D166: 67340 | E166: 66220 | F166: 212.58K | G166: -0.16
A167: 08/30/2024 | B167: 67430 | C167: 67870 | D167: 68800 | E167: 67430 | F167: 410.04K | G167: -0.46
A168: 08/29/2024 | B168: 67740 | C168: 66780 | D168: 67760 | E168: 66700 | F168: 267.21K | G168: 1.68
... A2642: 01/02/2015 | B2642: 13085 | C2642: 13250 | D2642: 13370 | E2642: 12990 | F2642: 614.38K | G2642: -1.06

Sheet Santander Stock Price History (
A1: Date | B1: Price | C1: Open | D1: High | E1: Low | F1: Vol. | G1: Change %
A2: 04/25/2025 | B2: 64160 | C2: 63060 | D2: 64160 | E2: 62860 | F2: 136.81K | G2: 2.59
A3: 04/24/2025 | B3: 62540 | C3: 62940 | D3: 63220 | E3: 62000 | F3: 20.99M | G3: -1.04
A4: 04/23/2025 | B4: 63200 | C4: 61620 | D4: 63370 | E4: 61600 | F4: 44.81M | G4: 4.41
A5: 04/22/2025 | B5: 60530 | C5: 59660 | D5: 60750 | E5: 59470 | F5: 25.14M | G5: 1.87
A6: 04/17/2025 | B6: 59420 | C6: 60100 | D6: 60270 | E6: 59130 | F6: 29.40M | G6: -1.38
A7: 04/16/2025 | B7: 60250 | C7: 59730 | D7: 60250 | E7: 59110 | F7: 4.33K | G7: 0.32
A8: 04/15/2025 | B8: 60060 | C8: 58250 | D8: 60350 | E8: 58150 | F8: 20.19K | G8: 3.59
A9: 04/14/2025 | B9: 57980 | C9: 57830 | D9: 58290 | E9: 56950 | F9: 30.00K | G9: 3.76
A10: 04/11/2025 | B10: 55880 | C10: 56740 | D10: 57080 | E10: 55100 | F10: 28.82K | G10: -1.31
A11: 04/10/2025 | B11: 56620 | C11: 63720 | D11: 63720 | E11: 56620 | F11: 33.93K | G11: 5.54
A12: 04/09/2025 | B12: 53650 | C12: 52800 | D12: 54650 | E12: 52520 | F12: 88.13K | G12: -2.53
A13: 04/08/2025 | B13: 55040 | C13: 54700 | D13: 56250 | E13: 52250 | F13: 38.07K | G13: 4.98
... A251: 05/06/2024 | B251: 45705 | C251: 45350 | D251: 45765 | E251: 45045 | F251: 22.36M | G251: 0.88
A252: 05/03/2024 | B252: 45305 | C252: 46000 | D252: 46000 | E252: 45140 | G252: -0.77
A253: 05/02/2024 | B253: 45655 | C253: 46065 | D253: 46200 | E253: 45410 | F253: 34.06M | G253: -0.16
A254: 04/30/2024 | B254: 45730 | C254: 46555 | D254: 47360 | E254: 45565 | F254: 57.11M | G254: -3.74
A255: 04/29/2024 | B255: 47505 | C255: 48900 | D255: 49280 | E255: 47285 | F255: 45.07M | G255: -2.06
A256: 04/26/2024 | B256: 48505 | C256: 48100 | D256: 48990 | E256: 47930 | F256: 41.12M | G256: 2.16
A257: 04/25/2024 | B257: 47480 | C257: 47905 | D257: 48265 | E257: 47060 | F257: 31.22M | G257: -0.66
A258: 04/24/2024 | B258: 47795 | C258: 47700 | D258: 47970 | E258: 47500 | F258: 34.67M | G258: 0.67
A259: 04/23/2024 | B259: 47475 | C259: 46985 | D259: 47665 | E259: 46860 | F259: 117.59M | G259: 1.72
A260: 04/22/2024 | B260: 46670 | C260: 45700 | D260: 46695 | E260: 45310 | F260: 43.01M | G260: 3.45
A261: 04/19/2024 | B261: 45115 | C261: 44800 | D261: 45300 | E261: 44570 | F261: 35.56M | G261: -0.73
A262: 04/18/2024 | B262: 45445 | C262: 44535 | D262: 45445 | E262: 44200 | F262: 34.34M | G262: 2.86
A263: 04/17/2024 | B263: 44180 | C263: 43700 | D263: 44605 | E263: 43675 | F263: 21.78M | G263: 1.4
A264: 04/16/2024 | B264: 43570 | C264: 44000 | D264: 44270 | E264: 43535 | F264: 40.19M | G264: -2.54
... A2640: 01/02/2015 | B2640: 61418 | C2640: 61890 | D2640: 62161 | E2640: 60623 | F2640: 45.27M | G2640: 0.5

Sheet Telefonica Stock Price History 
A1: Date | B1: Price | C1: Open | D1: High | E1: Low | F1: Vol. | G1: Change %
A2: 04/25/2025 | B2: 43950 | C2: 43540 | D2: 44250 | E2: 43430 | F2: 20.10K | G2: 0.83
A3: 04/24/2025 | B3: 43590 | C3: 43590 | D3: 43910 | E3: 43420 | F3: 5.54M | G3: 0.09
A4: 04/23/2025 | B4: 43550 | C4: 43800 | D4: 43950 | E4: 42830 | F4: 10.25M | G4: -0.27
A5: 04/22/2025 | B5: 43670 | C5: 42950 | D5: 43900 | E5: 42790 | F5: 24.89K | G5: 0.88
A6: 04/17/2025 | B6: 43290 | C6: 42690 | D6: 43360 | E6: 42360 | F6: 6.66K | G6: 1.41
A7: 04/16/2025 | B7: 42690 | C7: 41800 | D7: 42690 | E7: 41710 | F7: 10.49M | G7: 2.47
A8: 04/15/2025 | B8: 41660 | C8: 41320 | D8: 41700 | E8: 41290 | F8: 7.06M | G8: 1.09
A9: 04/14/2025 | B9: 41210 | C9: 40470 | D9: 41260 | E9: 40120 | F9: 9.11M | G9: 3.13
A10: 04/11/2025 | B10: 39960 | C10: 39500 | D10: 40020 | E10: 39130 | F10: 11.38M | G10: 1.16
A11: 04/10/2025 | B11: 39500 | C11: 42290 | D11: 42290 | E11: 39330 | F11: 0.79K | G11: 1.57
A12: 04/09/2025 | B12: 38890 | C12: 40110 | D12: 40380 | E12: 38330 | F12: 23.64M | G12: -4.7
A13: 04/08/2025 | B13: 40810 | C13: 41060 | D13: 41060 | E13: 39860 | F13: 6.56K | G13: -0.46
... A763: 05/05/2022 | B763: 47700 | C763: 47380 | D763: 47750 | E763: 47110 | F763: 14.36M | G763: 1.55
A764: 05/04/2022 | B764: 46970 | C764: 46850 | D764: 47500 | E764: 46400 | G764: 0.19
A765: 05/03/2022 | B765: 46880 | C765: 45990 | D765: 46880 | E765: 45800 | G765: 1.98
A766: 05/02/2022 | B766: 45970 | C766: 46000 | D766: 46900 | E766: 45600 | G766: -0.78
A767: 04/29/2022 | B767: 46330 | C767: 47000 | D767: 47060 | E767: 46150 | F767: 15.54M | G767: -1.49
A768: 04/28/2022 | B768: 47030 | C768: 46940 | D768: 47030 | E768: 46300 | F768: 13.42M | G768: 0.19
A769: 04/27/2022 | B769: 46940 | C769: 47390 | D769: 47430 | E769: 46700 | F769: 15.07M | G769: -1.1
A770: 04/26/2022 | B770: 47460 | C770: 48580 | D770: 48840 | E770: 47420 | F770: 16.00M | G770: -1.08
A771: 04/25/2022 | B771: 47980 | C771: 47990 | D771: 48660 | E771: 47670 | G771: -0.97
A772: 04/22/2022 | B772: 48450 | C772: 48070 | D772: 49000 | E772: 47770 | F772: 11.61M | G772: 0.12
A773: 04/21/2022 | B773: 48390 | C773: 48950 | D773: 49320 | E773: 48340 | F773: 20.49M | G773: -0.94
A774: 04/20/2022 | B774: 48850 | C774: 49100 | D774: 49370 | E774: 48530 | F774: 26.37M | G774: -1.17
A775: 04/19/2022 | B775: 49430 | C775: 49900 | D775: 50000 | E775: 49080 | F775: 18.97M | G775: -1.06
A776: 04/14/2022 | B776: 49960 | C776: 49500 | D776: 50000 | E776: 48920 | F776: 20.32M | G776: 1.17
A777: 04/13/2022 | B777: 49380 | C777: 48250 | D777: 49530 | E777: 48220 | F777: 21.09M | G777: 2.41
A778: 04/12/2022 | B778: 48220 | C778: 46560 | D778: 48270 | E778: 46380 | F778: 21.30M | G778: 3.08
A779: 04/11/2022 | B779: 46780 | C779: 46120 | D779: 46930 | E779: 45990 | F779: 13.41M | G779: 1.1
A780: 04/08/2022 | B780: 46270 | C780: 45890 | D780: 46300 | E780: 45660 | F780: 12.52M | G780: 1.69
A781: 04/07/2022 | B781: 45500 | C781: 45220 | D781: 46120 | E781: 45050 | F781: 12.77M | G781: 0.18
A782: 04/06/2022 | B782: 45420 | C782: 44880 | D782: 45420 | E782: 44640 | F782: 17.16M | G782: 1
A783: 04/05/2022 | B783: 44970 | C783: 44360 | D783: 44970 | E783: 44180 | F783: 11.01M | G783: 1.38
... A2640: 01/02/2015 | B2640: 116640 | C2640: 117760 | D2640: 118160 | E2640: 115560 | F2640: 11.20M | G2640: -0.29

Sheet Repsol Stock Price History
A1: Date | B1: Price | C1: Open | D1: High | E1: Low | F1: Vol. | G1: Change %
A2: 04/25/2025 | B2: 10720 | C2: 10665 | D2: 10745 | E2: 10570 | F2: 5.56K | G2: 1.56
A3: 04/24/2025 | B3: 10555 | C3: 10525 | D3: 10620 | E3: 10490 | F3: 3.03M | G3: 0.91
A4: 04/23/2025 | B4: 10460 | C4: 10500 | D4: 10665 | E4: 10400 | F4: 1.44K | G4: 1.31
A5: 04/22/2025 | B5: 10325 | C5: 10355 | D5: 10405 | E5: 10260 | F5: 3.60M | G5: 0
A6: 04/17/2025 | B6: 10325 | C6: 10245 | D6: 10340 | E6: 10085 | F6: 3.41M | G6: 1.72
A7: 04/16/2025 | B7: 10150 | C7: 9900 | D7: 10150 | E7: 9834 | F7: 3.69M | G7: 1.7
A8: 04/15/2025 | B8: 9980 | C8: 9930 | D8: 10065 | E8: 9882 | F8: 5.29M | G8: 0.46
A9: 04/14/2025 | B9: 9934 | C9: 9810 | D9: 10065 | E9: 9770 | F9: 5.67M | G9: 3.57
A10: 04/11/2025 | B10: 9592 | C10: 9768 | D10: 9770 | E10: 9550 | F10: 7.46M | G10: -1.76
A11: 04/10/2025 | B11: 9764 | C11: 11010 | D11: 11010 | E11: 9756 | F11: 10.22M | G11: 1.92
A12: 04/09/2025 | B12: 9580 | C12: 9706 | D12: 9706 | E12: 9414 | F12: 11.71M | G12: -3.82
A13: 04/08/2025 | B13: 9960 | C13: 10395 | D13: 10500 | E13: 9882 | F13: 11.46M | G13: -0.85
... A2640: 01/02/2015 | B2640: 11720 | C2640: 11856 | D2640: 11886 | E2640: 11622 | F2640: 6.67M | G2640: 0.15

Sheet Spain 10-Year Bond Yield Histor
A1: Date | B1: Price | C1: Open | D1: High | E1: Low | F1: Change %
A2: 04/22/2025 | B2: 3146 | C2: 3172 | D2: 3184 | E2: 3141 | F2: -0.76
A3: 04/21/2025 | B3: 3170 | C3: 3170 | D3: 3170 | E3: 3170 | F3: -0.03
A4: 04/18/2025 | B4: 3171 | C4: 3173 | D4: 3173 | E4: 3171 | F4: -0.09
A5: 04/17/2025 | B5: 3174 | C5: 3211 | D5: 3248 | E5: 3157 | F5: -1.03
A6: 04/16/2025 | B6: 3207 | C6: 3205 | D6: 3231 | E6: 3188 | F6: -1.03
A7: 04/15/2025 | B7: 3240 | C7: 3203 | D7: 3254 | E7: 3198 | F7: 0.82
A8: 04/14/2025 | B8: 3214 | C8: 3268 | D8: 3277 | E8: 3212 | F8: -2.34
A9: 04/11/2025 | B9: 3291 | C9: 3320 | D9: 3367 | E9: 3257 | F9: -0.57
A10: 04/10/2025 | B10: 3310 | C10: 3391 | D10: 3394 | E10: 3290 | F10: -1.15
A11: 04/09/2025 | B11: 3349 | C11: 3418 | D11: 3430 | E11: 3325 | F11: 0.03
A12: 04/08/2025 | B12: 3348 | C12: 3327 | D12: 3375 | E12: 3281 | F12: 0.15
A13: 04/07/2025 | B13: 3342 | C13: 3261 | D13: 3358 | E13: 3203 | F13: 2.41
... A2929: 01/01/2015 | B2929: 1611 | C2929: 1613 | D2929: 1613 | E2929: 1611 | F2929: 0.06

Sheet US 30 Year T-Bond Futures Histo
A1: Date | B1: Price | C1: Open | D1: High | E1: Low | F1: Vol. | G1: Change %
A2: 04/25/2025 | B2: 11581 | C2: 11503 | D2: 11628 | E2: 11488 | F2: 315.25K | G2: 0.54
A3: 04/24/2025 | B3: 11519 | C3: 11431 | D3: 11525 | E3: 11425 | F3: 333.37K | G3: 0.9
A4: 04/23/2025 | B4: 11416 | C4: 11406 | D4: 11597 | E4: 11391 | F4: 685.33K | G4: 0.5
A5: 04/22/2025 | B5: 11359 | C5: 11309 | D5: 11391 | E5: 11272 | F5: 385.99K | G5: 0.5
A6: 04/21/2025 | B6: 11303 | C6: 11431 | D6: 11441 | E6: 11284 | F6: 426.54K | G6: -1.34
A7: 04/17/2025 | B7: 11456 | C7: 11534 | D7: 11544 | E7: 11425 | F7: 308.98K | G7: -0.62
A8: 04/16/2025 | B8: 11528 | C8: 11475 | D8: 11547 | E8: 11438 | F8: 436.89K | G8: 0.38
A9: 04/15/2025 | B9: 11484 | C9: 11431 | D9: 11503 | E9: 11375 | F9: 397.32K | G9: 0.3
A10: 04/14/2025 | B10: 11450 | C10: 11334 | D10: 11456 | E10: 11250 | F10: 442.55K | G10: 1.16
A11: 04/11/2025 | B11: 11319 | C11: 11369 | D11: 11413 | E11: 11166 | F11: 817.78K | G11: -0.6
A12: 04/10/2025 | B12: 11388 | C12: 11522 | D12: 11634 | E12: 11350 | F12: 839.45K | G12: -0.57
A13: 04/09/2025 | B13: 11453 | C13: 11500 | D13: 11572 | E13: 11153 | F13: 1.46M | G13: -1.05
... A184: 08/05/2024 | B184: 12553 | C184: 12528 | D184: 12694 | E184: 12481 | F184: 3.81K | G184: 0.37
A185: 08/03/2024 | B185: 12506 | C185: 12506 | D185: 12506 | E185: 12506 | G185: -0.1
A186: 08/02/2024 | B186: 12519 | C186: 12278 | D186: 12538 | E186: 12278 | F186: 3.44K | G186: 2.06
A187: 08/01/2024 | B187: 12266 | C187: 12178 | D187: 12291 | E187: 12147 | F187: 1.02K | G187: 1.45
A188: 07/31/2024 | B188: 12091 | C188: 12034 | D188: 12191 | E188: 12022 | F188: 0.86K | G188: 0.52
A189: 07/30/2024 | B189: 12028 | C189: 11978 | D189: 12044 | E189: 11963 | F189: 0.57K | G189: 0.44
A190: 07/29/2024 | B190: 11975 | C190: 11963 | D190: 12022 | E190: 11956 | F190: 0.21K | G190: 0.31
A191: 07/27/2024 | B191: 11938 | C191: 11938 | D191: 11938 | E191: 11938 | G191: -0.05
A192: 07/26/2024 | B192: 11944 | C192: 11878 | D192: 11963 | E192: 11859 | F192: 0.09K | G192: 0.61
A193: 07/25/2024 | B193: 11872 | C193: 11822 | D193: 11931 | E193: 11822 | F193: 0.33K | G193: 0.5
A194: 07/24/2024 | B194: 11813 | C194: 11888 | D194: 11934 | E194: 11809 | F194: 0.76K | G194: -0.84
A195: 07/23/2024 | B195: 11913 | C195: 11900 | D195: 11941 | E195: 11894 | F195: 0.10K | G195: 0.21
A196: 07/22/2024 | B196: 11888 | C196: 11950 | D196: 11975 | E196: 11863 | F196: 0.53K | G196: -0.24
A197: 07/20/2024 | B197: 11916 | C197: 11916 | D197: 11916 | E197: 11916 | G197: -0.05
A198: 07/19/2024 | B198: 11922 | C198: 11988 | D198: 11991 | E198: 11906 | F198: 0.26K | G198: -0.57
A199: 07/18/2024 | B199: 11991 | C199: 12034 | D199: 12034 | E199: 11972 | F199: 0.41K | G199: -0.6
A200: 07/17/2024 | B200: 12063 | C200: 12038 | D200: 12063 | E200: 12003 | F200: 0.64K | G200: 0.21
A201: 07/16/2024 | B201: 12038 | C201: 11956 | D201: 12041 | E201: 11947 | F201: 0.73K | G201: 0.94
A202: 07/15/2024 | B202: 11925 | C202: 11931 | D202: 11947 | E202: 11881 | F202: 0.67K | G202: -0.55
A203: 07/13/2024 | B203: 11991 | C203: 11991 | D203: 11991 | E203: 11991 | G203: -0.1
A204: 07/12/2024 | B204: 12003 | C204: 11969 | D204: 12009 | E204: 11931 | F204: 0.11K | G204: 0.1
A205: 07/11/2024 | B205: 11991 | C205: 11878 | D205: 12034 | E205: 11863 | F205: 0.57K | G205: 0.92
A206: 07/10/2024 | B206: 11881 | C206: 11850 | D206: 11903 | E206: 11850 | F206: 0.12K | G206: 0.26
A207: 07/09/2024 | B207: 11850 | C207: 11872 | D207: 11881 | E207: 11819 | F207: 0.60K | G207: -0.5
A208: 07/08/2024 | B208: 11909 | C208: 11859 | D208: 11900 | E208: 11838 | F208: 1.20K | G208: 0.16
A209: 07/05/2024 | B209: 11891 | C209: 11759 | D209: 11897 | E209: 11759 | F209: 0.06K | G209: 1.12
A210: 07/04/2024 | B210: 11759 | C210: 11769 | D210: 11778 | E210: 11747 | F210: 46.21K | G210: -0.42
...

Sheet Germany 10-Year Bond Yield Hist
A1: Date | B1: Price | C1: Open | D1: High | E1: Low | F1: Change %
A2: 04/22/2025 | B2: 24470 | C2: 24810 | D2: 24810 | E2: 24410 | F2: -0.91
A3: 04/21/2025 | B3: 24695 | C3: 24690 | D3: 24695 | E3: 24690 | F3: 0.26
A4: 04/18/2025 | B4: 24630 | C4: 24690 | D4: 24690 | E4: 24630 | F4: -0.06
A5: 04/17/2025 | B5: 24645 | C5: 25110 | D5: 25380 | E5: 24530 | F5: -1.5
A6: 04/16/2025 | B6: 25020 | C6: 25360 | D6: 25360 | E6: 24790 | F6: -1.65
A7: 04/15/2025 | B7: 25440 | C7: 25040 | D7: 25510 | E7: 24930 | F7: 0.91
A8: 04/14/2025 | B8: 25210 | C8: 25710 | D8: 25800 | E8: 25090 | F8: -0.24
A9: 04/11/2025 | B9: 25270 | C9: 26120 | D9: 26320 | E9: 24900 | F9: -2.11
A10: 04/10/2025 | B10: 25815 | C10: 27070 | D10: 27150 | E10: 25680 | F10: 0.08
A11: 04/09/2025 | B11: 25795 | C11: 26260 | D11: 26750 | E11: 25570 | F11: -1.71
A12: 04/08/2025 | B12: 26245 | C12: 26490 | D12: 26800 | E12: 25740 | F12: 1.02
A13: 04/07/2025 | B13: 25980 | C13: 25770 | D13: 26680 | E13: 24310 | F13: 1.11
... A2339: 09/23/2016 | B2339: -810 | C2339: -850 | D2339: -720 | E2339: -930 | F2339: -14.74
A2340: 09/22/2016 | B2340: -950 | C2340: 50 | D2340: 50 | E2340: -950
A2341: 09/21/2016 | B2341: 30 | C2341: -140 | D2341: 140 | E2341: -210 | F2341: -117.65
A2342: 09/20/2016 | B2342: -170 | C2342: 210 | D2342: 210 | E2342: -210 | F2342: -194.44
A2343: 09/19/2016 | B2343: 180 | C2343: 70 | D2343: 250 | E2343: -90 | F2343: 800
A2344: 09/17/2016 | B2344: 20 | C2344: 20 | D2344: 20 | E2344: 20 | F2344: -71.43
A2345: 09/16/2016 | B2345: 70 | C2345: 310 | D2345: 320 | E2345: -240 | F2345: -79.41
A2346: 09/15/2016 | B2346: 340 | C2346: 260 | D2346: 650 | E2346: 190 | F2346: 54.55
A2347: 09/14/2016 | B2347: 220 | C2347: 760 | D2347: 810 | E2347: 180 | F2347: -69.44
A2348: 09/13/2016 | B2348: 720 | C2348: 330 | D2348: 730 | E2348: 10 | F2348: 94.59
A2349: 09/12/2016 | B2349: 370 | C2349: 220 | D2349: 580 | E2349: 150 | F2349: 208.33
A2350: 09/09/2016 | B2350: 120 | C2350: -530 | D2350: 210 | E2350: -530 | F2350: -119.35
A2351: 09/08/2016 | B2351: -620 | C2351: -1150 | D2351: -540 | E2351: -1230 | F2351: -46.55
A2352: 09/07/2016 | B2352: -1160 | C2352: -1100 | D2352: -1040 | E2352: -1270 | F2352: 6.42
... A2414: 06/16/2016 | B2414: -224 | C2414: -290 | D2414: -50 | E2414: -380 | F2414: 60
A2415: 06/15/2016 | B2415: -140 | C2415: 70 | D2415: 190 | E2415: -160
A2416: 06/14/2016 | B2416: -10 | C2416: 170 | D2416: 290 | E2416: -340 | F2416: -103.33
A2417: 06/13/2016 | B2417: 300 | C2417: 140 | D2417: 370 | E2417: 110 | F2417: 42.86
A2418: 06/10/2016 | B2418: 210 | C2418: 340 | D2418: 420 | E2418: 100 | F2418: -43.24
A2419: 06/09/2016 | B2419: 370 | C2419: 470 | D2419: 530 | E2419: 230 | F2419: -38.33
A2420: 06/08/2016 | B2420: 600 | C2420: 560 | D2420: 710 | E2420: 330 | F2420: 9.09
A2421: 06/07/2016 | B2421: 550 | C2421: 820 | D2421: 930 | E2421: 460 | F2421: -36.05
A2422: 06/06/2016 | B2422: 860 | C2422: 700 | D2422: 880 | E2422: 670 | F2422: 16.22
A2423: 06/03/2016 | B2423: 740 | C2423: 1200 | D2423: 1230 | E2423: 650 | F2423: -33.93
A2424: 06/02/2016 | B2424: 1120 | C2424: 1390 | D2424: 1600 | E2424: 1090 | F2424: -16.42
A2425: 06/01/2016 | B2425: 1340 | C2425: 1360 | D2425: 1440 | E2425: 1190 | F2425: -8.84
A2426: 05/31/2016 | B2426: 1470 | C2426: 1670 | D2426: 1920 | E2426: 1460 | F2426: -11.98
...

Sheet EUR_USD Historical Data (2)
A1: Date | B1: Price | C1: Open | D1: High | E1: Low | F1: Vol. | G1: Change %
A2: 04/25/2025 | B2: 11364 | C2: 11389 | D2: 11395 | E2: 11315 | G2: -0.21
A3: 04/24/2025 | B3: 11388 | C3: 11315 | D3: 11399 | E3: 11313 | G3: 0.66
A4: 04/23/2025 | B4: 11313 | C4: 11422 | D4: 11441 | E4: 11308 | G4: -0.94
A5: 04/22/2025 | B5: 11420 | C5: 11515 | D5: 11548 | E5: 11417 | G5: -0.81
A6: 04/21/2025 | B6: 11513 | C6: 11385 | D6: 11574 | E6: 11388 | G6: 1.07
A7: 04/18/2025 | B7: 11391 | C7: 11367 | D7: 11399 | E7: 11358 | G7: 0.25
A8: 04/17/2025 | B8: 11363 | C8: 11395 | D8: 11410 | E8: 11336 | G8: -0.31
A9: 04/16/2025 | B9: 11398 | C9: 11283 | D9: 11413 | E9: 11281 | G9: 1.04
A10: 04/15/2025 | B10: 11281 | C10: 11349 | D10: 11379 | E10: 11264 | G10: -0.6
A11: 04/14/2025 | B11: 11349 | C11: 11313 | D11: 11425 | E11: 11282 | G11: -0.1
A12: 04/11/2025 | B12: 11360 | C12: 11202 | D12: 11475 | E12: 11189 | G12: 1.46
A13: 04/10/2025 | B13: 11197 | C13: 10951 | D13: 11242 | E13: 10943 | G13: 2.25
... A2693: 01/01/2015 | B2693: 12102 | C2693: 12098 | D2693: 12107 | E2693: 12094 | G2693: 0.04

Sheet hoja intermedia
B1: =SUM(B3:B2641) -> 104061.59 | C1: =SUM(C3:C2641) -> 16796.941 | D1: =SUM(D3:D2641) -> 31029.344 | E1: =SUM(E3:E2641) -> #N/A | F1: =SUM(F3:F2641) -> #N/A | G1: =SUM(G3:G2641) -> #N/A | H1: =SUM(H3:H2641) -> 1157357 | I1: =SUM(I3:I2641) -> #N/A | ... V1: =SUM(V3:V2641) -> 2948.1721
A2: Date | B2: Santander | C2: Telefónica | D2: Repsol | E2: Microsoft | F2: Alphabet | G2: Tesla | H2: LVM | I2: us 30Y bond | J2: Germany 10y Bond | K2: España 10 y Bono | L2: Santander | M2: Telefónica | N2: Repsol | O2: Microsoft | P2: Alphabet | Q2: Tesla | R2: LVM | S2: us 30Y bond | T2: Germany 10y Bond | U2: España 10 y Bono | V2: EURUSD
A3: 04/25/2025 | B3: 64.16 | C3: 4.395 | D3: 10.72 | E3: 391.85 | F3: 163.85 | G3: 284.95 | H3: 498.8 | I3: 1.1581 | J3: 2.445 | K3: 3.147 | L3: 6.416 | M3: =IFERROR(C3,C4) -> 4.395 | N3: =IFERROR(D3,D4) -> 10.72 | O3: =IFERROR(E3,E4) -> 391.85 | P3: =IFERROR(F3,F4) -> 163.85 | Q3: =IFERROR(G3,G4) -> 284.95 | R3: =IFERROR(H3,H4) -> 498.8 | S3: =IFERROR(I3,I4) -> 1.1581 | T3: =IFERROR(J3,J4) -> 2.445 | U3: =IFERROR(K3,K4) -> 3.147 | V3: 1.1364
A4: 04/24/2025 | B4: 62.54 | C4: 4.359 | D4: 10.555 | E4: 387.3 | F4: 161.47 | G4: 259.51 | H4: 499.7 | I4: 1.1519 | J4: 2.438 | K4: 3.135 | L4: 6.254 | M4: =IFERROR(C4,C5) -> 4.359 | N4: =IFERROR(D4,D5) -> 10.555 | O4: =IFERROR(E4,E5) -> 387.3 | P4: =IFERROR(F4,F5) -> 161.47 | Q4: =IFERROR(G4,G5) -> 259.51 | R4: =IFERROR(H4,H5) -> 499.7 | S4: =IFERROR(I4,I5) -> 1.1519 | T4: =IFERROR(J4,J5) -> 2.438 | U4: =IFERROR(K4,K5) -> 3.135 | V4: 1.1388
A5: 04/23/2025 | B5: 63.2 | C5: 4.355 | D5: 10.46 | E5: 374.39 | F5: 157.72 | G5: 250.74 | H5: 500.3 | I5: 1.1416 | J5: 2.435 | K5: 3.128 | L5: 6.32 | M5: =IFERROR(C5,C6) -> 4.355 | N5: =IFERROR(D5,D6) -> 10.46 | O5: =IFERROR(E5,E6) -> 374.39 | P5: =IFERROR(F5,F6) -> 157.72 | Q5: =IFERROR(G5,G6) -> 250.74 | R5: =IFERROR(H5,H6) -> 500.3 | S5: =IFERROR(I5,I6) -> 1.1416 | T5: =IFERROR(J5,J6) -> 2.435 | U5: =IFERROR(K5,K6) -> 3.128 | V5: 1.1313
A6: 04/22/2025 | B6: 60.53 | C6: 4.367 | D6: 10.325 | E6: 366.82 | F6: 153.9 | G6: 237.97 | H6: 487.3 | I6: 1.1359 | J6: 2.447 | K6: 3.146 | L6: 6.053 | M6: =IFERROR(C6,C7) -> 4.367 | N6: =IFERROR(D6,D7) -> 10.325 | O6: =IFERROR(E6,E7) -> 366.82 | P6: =IFERROR(F6,F7) -> 153.9 | Q6: =IFERROR(G6,G7) -> 237.97 | R6: =IFERROR(H6,H7) -> 487.3 | S6: =IFERROR(I6,I7) -> 1.1359 | T6: =IFERROR(J6,J7) -> 2.447 | U6: =IFERROR(K6,K7) -> 3.146 | V6: 1.142
A7: 04/17/2025 | B7: 59.42 | C7: 4.329 | D7: 10.325 | E7: 367.78 | F7: 153.36 | G7: 241.37 | H7: 485.6 | I7: 1.1456 | J7: 2.4645 | K7: 3.174 | L7: 5.942 | M7: =IFERROR(C7,C8) -> 4.329 | N7: =IFERROR(D7,D8) -> 10.325 | O7: =IFERROR(E7,E8) -> 367.78 | P7: =IFERROR(F7,F8) -> 153.36 | Q7: =IFERROR(G7,G8) -> 241.37 | R7: =IFERROR(H7,H8) -> 485.6 | S7: =IFERROR(I7,I8) -> 1.1456 | T7: =IFERROR(J7,J8) -> 2.4645 | U7: =IFERROR(K7,K8) -> 3.174 | V7: 1.1363
A8: 04/16/2025 | B8: 60.25 | C8: 4.269 | D8: 10.15 | E8: 371.61 | F8: 155.5 | G8: 241.55 | H8: 485.2 | I8: 1.1528 | J8: 2.502 | K8: 3.207 | L8: 6.025 | M8: =IFERROR(C8,C9) -> 4.269 | N8: =IFERROR(D8,D9) -> 10.15 | O8: =IFERROR(E8,E9) -> 371.61 | P8: =IFERROR(F8,F9) -> 155.5 | Q8: =IFERROR(G8,G9) -> 241.55 | R8: =IFERROR(H8,H9) -> 485.2 | S8: =IFERROR(I8,I9) -> 1.1528 | T8: =IFERROR(J8,J9) -> 2.502 | U8: =IFERROR(K8,K9) -> 3.207 | V8: 1.1398
A9: 04/15/2025 | B9: 60.06 | C9: 4.166 | D9: 9.98 | E9: 385.73 | F9: 158.68 | G9: 254.11 | H9: 488.65 | I9: 1.1484 | J9: 2.544 | K9: 3.24 | L9: 6.006 | M9: =IFERROR(C9,C10) -> 4.166 | N9: =IFERROR(D9,D10) -> 9.98 | O9: =IFERROR(E9,E10) -> 385.73 | P9: =IFERROR(F9,F10) -> 158.68 | Q9: =IFERROR(G9,G10) -> 254.11 | R9: =IFERROR(H9,H10) -> 488.65 | S9: =IFERROR(I9,I10) -> 1.1484 | T9: =IFERROR(J9,J10) -> 2.544 | U9: =IFERROR(K9,K10) -> 3.24 | V9: 1.1281
A10: 04/14/2025 | B10: 57.98 | C10: 4.121 | D10: 9.934 | E10: 387.81 | F10: 161.47 | G10: 252.35 | H10: 530.1 | I10: 1.145 | J10: 2.521 | K10: 3.214 | L10: 5.798 | M10: =IFERROR(C10,C11) -> 4.121 | N10: =IFERROR(D10,D11) -> 9.934 | O10: =IFERROR(E10,E11) -> 387.81 | P10: =IFERROR(F10,F11) -> 161.47 | Q10: =IFERROR(G10,G11) -> 252.35 | R10: =IFERROR(H10,H11) -> 530.1 | S10: =IFERROR(I10,I11) -> 1.145 | T10: =IFERROR(J10,J11) -> 2.521 | U10: =IFERROR(K10,K11) -> 3.214 | V10: 1.1349
A11: 04/11/2025 | B11: 55.88 | C11: 3.996 | D11: 9.592 | E11: 388.45 | F11: 159.4 | G11: 252.31 | H11: 524.4 | I11: 1.1319 | J11: 2.527 | K11: 3.291 | L11: 5.588 | M11: =IFERROR(C11,C12) -> 3.996 | N11: =IFERROR(D11,D12) -> 9.592 | O11: =IFERROR(E11,E12) -> 388.45 | P11: =IFERROR(F11,F12) -> 159.4 | Q11: =IFERROR(G11,G12) -> 252.31 | R11: =IFERROR(H11,H12) -> 524.4 | S11: =IFERROR(I11,I12) -> 1.1319 | T11: =IFERROR(J11,J12) -> 2.527 | U11: =IFERROR(K11,K12) -> 3.291 | V11: 1.136
A12: 04/10/2025 | B12: 56.62 | C12: 3.95 | D12: 9.764 | E12: 381.35 | F12: 155.37 | G12: 252.4 | H12: 524.2 | I12: 1.1388 | J12: 2.5815 | K12: 3.31 | L12: 5.662 | M12: =IFERROR(C12,C13) -> 3.95 | N12: =IFERROR(D12,D13) -> 9.764 | O12: =IFERROR(E12,E13) -> 381.35 | P12: =IFERROR(F12,F13) -> 155.37 | Q12: =IFERROR(G12,G13) -> 252.4 | R12: =IFERROR(H12,H13) -> 524.2 | S12: =IFERROR(I12,I13) -> 1.1388 | T12: =IFERROR(J12,J13) -> 2.5815 | U12: =IFERROR(K12,K13) -> 3.31 | V12: 1.1197
A13: 04/09/2025 | B13: 53.65 | C13: 3.889 | D13: 9.58 | E13: 390.49 | F13: 161.06 | G13: 272.2 | H13: 498.4 | I13: 1.1453 | J13: 2.5795 | K13: 3.349 | L13: 5.365 | M13: =IFERROR(C13,C14) -> 3.889 | N13: =IFERROR(D13,D14) -> 9.58 | O13: =IFERROR(E13,E14) -> 390.49 | P13: =IFERROR(F13,F14) -> 161.06 | Q13: =IFERROR(G13,G14) -> 272.2 | R13: =IFERROR(H13,H14) -> 498.4 | S13: =IFERROR(I13,I14) -> 1.1453 | T13: =IFERROR(J13,J14) -> 2.5795 | U13: =IFERROR(K13,K14) -> 3.349 | V13: 1.0951
A14: 04/08/2025 | B14: 55.04 | C14: 4.081 | D14: 9.96 | E14: 354.56 | F14: 146.58 | G14: 221.86 | H14: 519.8 | I14: 1.1575 | J14: 2.6245 | K14: 3.348 | L14: 5.504 | M14: =IFERROR(C14,C15) -> 4.081 | N14: =IFERROR(D14,D15) -> 9.96 | O14: =IFERROR(E14,E15) -> 354.56 | P14: =IFERROR(F14,F15) -> 146.58 | Q14: =IFERROR(G14,G15) -> 221.86 | R14: =IFERROR(H14,H15) -> 519.8 | S14: =IFERROR(I14,I15) -> 1.1575 | T14: =IFERROR(J14,J15) -> 2.6245 | U14: =IFERROR(K14,K15) -> 3.348 | V14: 1.0956
... A49: 02/18/2025 | B49: 59.61 | C49: 4.144 | D49: 12.155 | E49: 409.64 | F49: 185.8 | G49: 354.11 | H49: 705.1 | I49: 1.1466 | J49: 2.4905 | K49: 3.143 | L49: 5.961 | M49: =IFERROR(C49,C50) -> 4.144 | N49: =IFERROR(D49,D50) -> 12.155 | O49: =IFERROR(E49,E50) -> 409.64 | P49: =IFERROR(F49,F50) -> 185.8 | Q49: =IFERROR(G49,G50) -> 354.11 | R49: =IFERROR(H49,H50) -> 705.1 | S49: =IFERROR(I49,I50) -> 1.1466 | T49: =IFERROR(J49,J50) -> 2.4905 | U49: =IFERROR(K49,K50) -> 3.143 | V49: 1.0445
A50: 02/17/2025 | B50: 58.1 | C50: 4.144 | D50: 12.12 | E50: #N/A | F50: #N/A | G50: #N/A | H50: 701.5 | I50: #N/A | J50: 2.483 | K50: 3.144 | L50: 5.81 | M50: =IFERROR(C50,C51) -> 4.144 | N50: =IFERROR(D50,D51) -> 12.12 | O50: =IFERROR(E50,E51) -> 408.43 | P50: =IFERROR(F50,F51) -> 186.87 | Q50: =IFERROR(G50,G51) -> 355.84 | R50: =IFERROR(H50,H51) -> 701.5 | S50: =IFERROR(I50,I51) -> 1.1553 | T50: =IFERROR(J50,J51) -> 2.483 | U50: =IFERROR(K50,K51) -> 3.144 | V50: 1.0482
A51: 02/14/2025 | B51: 57.92 | C51: 4.137 | D51: 12.135 | E51: 408.43 | F51: 186.87 | G51: 355.84 | H51: 713 | I51: 1.1553 | J51: 2.423 | K51: 3.099 | L51: 5.792 | M51: =IFERROR(C51,C52) -> 4.137 | N51: =IFERROR(D51,D52) -> 12.135 | O51: =IFERROR(E51,E52) -> 408.43 | P51: =IFERROR(F51,F52) -> 186.87 | Q51: =IFERROR(G51,G52) -> 355.84 | R51: =IFERROR(H51,H52) -> 713 | S51: =IFERROR(I51,I52) -> 1.1553 | T51: =IFERROR(J51,J52) -> 2.423 | U51: =IFERROR(K51,K52) -> 3.099 | V51: 1.0491
A52: 02/13/2025 | B52: 57.21 | C52: 4.203 | D52: 11.945 | E52: 410.54 | F52: 187.88 | G52: 355.94 | H52: 707.2 | I52: 1.15 | J52: 2.419 | K52: 3.076 | L52: 5.721 | M52: =IFERROR(C52,C53) -> 4.203 | N52: =IFERROR(D52,D53) -> 11.945 | O52: =IFERROR(E52,E53) -> 410.54 | P52: =IFERROR(F52,F53) -> 187.88 | Q52: =IFERROR(G52,G53) -> 355.94 | R52: =IFERROR(H52,H53) -> 707.2 | S52: =IFERROR(I52,I53) -> 1.15 | T52: =IFERROR(J52,J53) -> 2.419 | U52: =IFERROR(K52,K53) -> 3.076 | V52: 1.0464
A53: 02/12/2025 | B53: 57.67 | C53: 4.216 | D53: 12.065 | E53: 409.04 | F53: 185.43 | G53: 336.51 | H53: 687.8 | I53: 1.1341 | J53: 2.478 | K53: 3.145 | L53: 5.767 | M53: =IFERROR(C53,C54) -> 4.216 | N53: =IFERROR(D53,D54) -> 12.065 | O53: =IFERROR(E53,E54) -> 409.04 | P53: =IFERROR(F53,F54) -> 185.43 | Q53: =IFERROR(G53,G54) -> 336.51 | R53: =IFERROR(H53,H54) -> 687.8 | S53: =IFERROR(I53,I54) -> 1.1341 | T53: =IFERROR(J53,J54) -> 2.478 | U53: =IFERROR(K53,K54) -> 3.145 | V53: 1.0382
A54: 02/11/2025 | B54: 56.56 | C54: 4.185 | D54: 11.78 | E54: 411.44 | F54: 187.07 | G54: 328.5 | H54: 685.2 | I54: 1.1478 | J54: 2.427 | K54: 3.105 | L54: 5.656 | M54: =IFERROR(C54,C55) -> 4.185 | N54: =IFERROR(D54,D55) -> 11.78 | O54: =IFERROR(E54,E55) -> 411.44 | P54: =IFERROR(F54,F55) -> 187.07 | Q54: =IFERROR(G54,G55) -> 328.5 | R54: =IFERROR(H54,H55) -> 685.2 | S54: =IFERROR(I54,I55) -> 1.1478 | T54: =IFERROR(J54,J55) -> 2.427 | U54: =IFERROR(K54,K55) -> 3.105 | V54: 1.036
A55: 02/10/2025 | B55: 54.84 | C55: 4.135 | D55: 11.57 | E55: 412.22 | F55: 188.2 | G55: 350.73 | H55: 685.3 | I55: 1.1541 | J55: 2.36 | K55: 3.032 | L55: 5.484 | M55: =IFERROR(C55,C56) -> 4.135 | N55: =IFERROR(D55,D56) -> 11.57 | O55: =IFERROR(E55,E56) -> 412.22 | P55: =IFERROR(F55,F56) -> 188.2 | Q55: =IFERROR(G55,G56) -> 350.73 | R55: =IFERROR(H55,H56) -> 685.3 | S55: =IFERROR(I55,I56) -> 1.1541 | T55: =IFERROR(J55,J56) -> 2.36 | U55: =IFERROR(K55,K56) -> 3.032 | V55: 1.0306
A56: 02/07/2025 | B56: 55.27 | C56: 4.102 | D56: 11.545 | E56: 409.75 | F56: 187.14 | G56: 361.62 | H56: 684.2 | I56: 1.1553 | J56: 2.377 | K56: 3.041 | L56: 5.527 | M56: =IFERROR(C56,C57) -> 4.102 | N56: =IFERROR(D56,D57) -> 11.545 | O56: =IFERROR(E56,E57) -> 409.75 | P56: =IFERROR(F56,F57) -> 187.14 | Q56: =IFERROR(G56,G57) -> 361.62 | R56: =IFERROR(H56,H57) -> 684.2 | S56: =IFERROR(I56,I57) -> 1.1553 | T56: =IFERROR(J56,J57) -> 2.377 | U56: =IFERROR(K56,K57) -> 3.041 | V56: 1.0327
A57: 02/06/2025 | B57: 56.28 | C57: 4.043 | D57: 11.5 | E57: 415.82 | F57: 193.31 | G57: 374.32 | H57: 696.9 | I57: 1.1609 | J57: 2.3725 | K57: 3.032 | L57: 5.628 | M57: =IFERROR(C57,C58) -> 4.043 | N57: =IFERROR(D57,D58) -> 11.5 | O57: =IFERROR(E57,E58) -> 415.82 | P57: =IFERROR(F57,F58) -> 193.31 | Q57: =IFERROR(G57,G58) -> 374.32 | R57: =IFERROR(H57,H58) -> 696.9 | S57: =IFERROR(I57,I58) -> 1.1609 | T57: =IFERROR(J57,J58) -> 2.3725 | U57: =IFERROR(K57,K58) -> 3.032 | V57: 1.0381
A58: 02/05/2025 | B58: 54.02 | C58: 3.977 | D58: 11.445 | E58: 413.29 | F58: 193.3 | G58: 378.17 | H58: 686 | I58: 1.1616 | J58: 2.359 | K58: 3.03 | L58: 5.402 | M58: =IFERROR(C58,C59) -> 3.977 | N58: =IFERROR(D58,D59) -> 11.445 | O58: =IFERROR(E58,E59) -> 413.29 | P58: =IFERROR(F58,F59) -> 193.3 | Q58: =IFERROR(G58,G59) -> 378.17 | R58: =IFERROR(H58,H59) -> 686 | S58: =IFERROR(I58,I59) -> 1.1616 | T58: =IFERROR(J58,J59) -> 2.359 | U58: =IFERROR(K58,K59) -> 3.03 | V58: 1.0402
A59: 02/04/2025 | B59: 49.885 | C59: 3.919 | D59: 11.48 | E59: 412.37 | F59: 207.71 | G59: 392.21 | H59: 692.7 | I59: 1.1475 | J59: 2.3925 | K59: 3.059 | L59: 4.9885 | M59: =IFERROR(C59,C60) -> 3.919 | N59: =IFERROR(D59,D60) -> 11.48 | O59: =IFERROR(E59,E60) -> 412.37 | P59: =IFERROR(F59,F60) -> 207.71 | Q59: =IFERROR(G59,G60) -> 392.21 | R59: =IFERROR(H59,H60) -> 692.7 | S59: =IFERROR(I59,I60) -> 1.1475 | T59: =IFERROR(J59,J60) -> 2.3925 | U59: =IFERROR(K59,K60) -> 3.059 | V59: 1.0377
A60: 02/03/2025 | B60: 48.415 | C60: 3.961 | D60: 11.31 | E60: 410.92 | F60: 202.64 | G60: 383.68 | H60: 690.1 | I60: 1.1438 | J60: 2.387 | K60: 3.057 | L60: 4.8415 | M60: =IFERROR(C60,C61) -> 3.961 | N60: =IFERROR(D60,D61) -> 11.31 | O60: =IFERROR(E60,E61) -> 410.92 | P60: =IFERROR(F60,F61) -> 202.64 | Q60: =IFERROR(G60,G61) -> 383.68 | R60: =IFERROR(H60,H61) -> 690.1 | S60: =IFERROR(I60,I61) -> 1.1438 | T60: =IFERROR(J60,J61) -> 2.387 | U60: =IFERROR(K60,K61) -> 3.057 | V60: 1.0344
A61: 01/31/2025 | B61: 49.64 | C61: 3.935 | D61: 11.27 | E61: 415.06 | F61: 205.6 | G61: 404.6 | H61: 703.5 | I61: 1.1391 | J61: 2.459 | K61: 3.113 | L61: 4.964 | M61: =IFERROR(C61,C62) -> 3.935 | N61: =IFERROR(D61,D62) -> 11.27 | O61: =IFERROR(E61,E62) -> 415.06 | P61: =IFERROR(F61,F62) -> 205.6 | Q61: =IFERROR(G61,G62) -> 404.6 | R61: =IFERROR(H61,H62) -> 703.5 | S61: =IFERROR(I61,I62) -> 1.1391 | T61: =IFERROR(J61,J62) -> 2.459 | U61: =IFERROR(K61,K62) -> 3.113 | V61: 1.0362
A62: 01/30/2025 | B62: 50.27 | C62: 3.966 | D62: 11.335 | E62: 414.99 | F62: 202.63 | G62: 400.28 | H62: 715.8 | I62: 1.1466 | J62: 2.517 | K62: 3.115 | L62: 5.027 | M62: =IFERROR(C62,C63) -> 3.966 | N62: =IFERROR(D62,D63) -> 11.335 | O62: =IFERROR(E62,E63) -> 414.99 | P62: =IFERROR(F62,F63) -> 202.63 | Q62: =IFERROR(G62,G63) -> 400.28 | R62: =IFERROR(H62,H63) -> 715.8 | S62: =IFERROR(I62,I63) -> 1.1466 | T62: =IFERROR(J62,J63) -> 2.517 | U62: =IFERROR(K62,K63) -> 3.115 | V62: 1.039
... A69: 01/21/2025 | B69: 47.895 | C69: 3.887 | D69: 11.43 | E69: 428.5 | F69: 199.63 | G69: 424.07 | H69: 701.3 | I69: 1.1366 | J69: 2.477 | K69: 3.138 | L69: 4.7895 | M69: =IFERROR(C69,C70) -> 3.887 | N69: =IFERROR(D69,D70) -> 11.43 | O69: =IFERROR(E69,E70) -> 428.5 | P69: =IFERROR(F69,F70) -> 199.63 | Q69: =IFERROR(G69,G70) -> 424.07 | R69: =IFERROR(H69,H70) -> 701.3 | S69: =IFERROR(I69,I70) -> 1.1366 | T69: =IFERROR(J69,J70) -> 2.477 | U69: =IFERROR(K69,K70) -> 3.138 | V69: 1.0429
A70: 01/20/2025 | B70: 48.95 | C70: 3.862 | D70: 11.5 | E70: #N/A | F70: #N/A | G70: #N/A | H70: 683.1 | I70: #N/A | J70: 2.4925 | K70: 3.153 | L70: 4.895 | M70: =IFERROR(C70,C71) -> 3.862 | N70: =IFERROR(D70,D71) -> 11.5 | O70: =IFERROR(E70,E71) -> 429.03 | P70: =IFERROR(F70,F71) -> 197.55 | Q70: =IFERROR(G70,G71) -> 426.5 | R70: =IFERROR(H70,H71) -> 683.1 | S70: =IFERROR(I70,I71) -> 1.1309 | T70: =IFERROR(J70,J71) -> 2.4925 | U70: =IFERROR(K70,K71) -> 3.153 | V70: 1.0414
A71: 01/17/2025 | B71: 47.995 | C71: 3.97 | D71: 11.625 | E71: 429.03 | F71: 197.55 | G71: 426.5 | H71: 690.1 | I71: 1.1309 | J71: 2.503 | K71: 3.17 | L71: 4.7995 | M71: =IFERROR(C71,C72) -> 3.97 | N71: =IFERROR(D71,D72) -> 11.625 | O71: =IFERROR(E71,E72) -> 429.03 | P71: =IFERROR(F71,F72) -> 197.55 | Q71: =IFERROR(G71,G72) -> 426.5 | R71: =IFERROR(H71,H72) -> 690.1 | S71: =IFERROR(I71,I72) -> 1.1309 | T71: =IFERROR(J71,J72) -> 2.503 | U71: =IFERROR(K71,K72) -> 3.17 | V71: 1.0271
A72: 01/16/2025 | B72: 47.825 | C72: 3.955 | D72: 11.555 | E72: 424.58 | F72: 194.41 | G72: 413.82 | H72: 695.5 | I72: 1.13 | J72: 2.5205 | K72: 3.18 | L72: 4.7825 | M72: =IFERROR(C72,C73) -> 3.955 | N72: =IFERROR(D72,D73) -> 11.555 | O72: =IFERROR(E72,E73) -> 424.58 | P72: =IFERROR(F72,F73) -> 194.41 | Q72: =IFERROR(G72,G73) -> 413.82 | R72: =IFERROR(H72,H73) -> 695.5 | S72: =IFERROR(I72,I73) -> 1.13 | T72: =IFERROR(J72,J73) -> 2.5205 | U72: =IFERROR(K72,K73) -> 3.18 | V72: 1.0298
A73: 01/15/2025 | B73: 47.655 | C73: 3.973 | D73: 11.73 | E73: 426.31 | F73: 196.98 | G73: 428.22 | H73: 637.2 | I73: 1.1253 | J73: 2.5275 | K73: 3.201 | L73: 4.7655 | M73: =IFERROR(C73,C74) -> 3.973 | N73: =IFERROR(D73,D74) -> 11.73 | O73: =IFERROR(E73,E74) -> 426.31 | P73: =IFERROR(F73,F74) -> 196.98 | Q73: =IFERROR(G73,G74) -> 428.22 | R73: =IFERROR(H73,H74) -> 637.2 | S73: =IFERROR(I73,I74) -> 1.1253 | T73: =IFERROR(J73,J74) -> 2.5275 | U73: =IFERROR(K73,K74) -> 3.201 | V73: 1.0289
A74: 01/14/2025 | B74: 46.86 | C74: 3.914 | D74: 11.67 | E74: 415.67 | F74: 191.05 | G74: 396.36 | H74: 651 | I74: 1.1091 | J74: 2.6225 | K74: 3.323 | L74: 4.686 | M74: =IFERROR(C74,C75) -> 3.914 | N74: =IFERROR(D74,D75) -> 11.67 | O74: =IFERROR(E74,E75) -> 415.67 | P74: =IFERROR(F74,F75) -> 191.05 | Q74: =IFERROR(G74,G75) -> 396.36 | R74: =IFERROR(H74,H75) -> 651 | S74: =IFERROR(I74,I75) -> 1.1091 | T74: =IFERROR(J74,J75) -> 2.6225 | U74: =IFERROR(K74,K75) -> 3.323 | V74: 1.0307
A75: 01/13/2025 | B75: 45.88 | C75: 3.906 | D75: 11.9 | E75: 417.19 | F75: 192.29 | G75: 403.31 | H75: 646.4 | I75: 1.1084 | J75: 2.5905 | K75: 3.302 | L75: 4.588 | M75: =IFERROR(C75,C76) -> 3.906 | N75: =IFERROR(D75,D76) -> 11.9 | O75: =IFERROR(E75,E76) -> 417.19 | P75: =IFERROR(F75,F76) -> 192.29 | Q75: =IFERROR(G75,G76) -> 403.31 | R75: =IFERROR(H75,H76) -> 646.4 | S75: =IFERROR(I75,I76) -> 1.1084 | T75: =IFERROR(J75,J76) -> 2.5905 | U75: =IFERROR(K75,K76) -> 3.302 | V75: 1.0244
A76: 01/10/2025 | B76: 45.685 | C76: 3.9 | D76: 11.695 | E76: 418.95 | F76: 193.17 | G76: 394.74 | H76: 645 | I76: 1.1122 | J76: 2.5675 | K76: 3.261 | L76: 4.5685 | M76: =IFERROR(C76,C77) -> 3.9 | N76: =IFERROR(D76,D77) -> 11.695 | O76: =IFERROR(E76,E77) -> 418.95 | P76: =IFERROR(F76,F77) -> 193.17 | Q76: =IFERROR(G76,G77) -> 394.74 | R76: =IFERROR(H76,H77) -> 645 | S76: =IFERROR(I76,I77) -> 1.1122 | T76: =IFERROR(J76,J77) -> 2.5675 | U76: =IFERROR(K76,K77) -> 3.261 | V76: 1.0244
A77: 01/09/2025 | B77: 45.695 | C77: 3.916 | D77: 12.05 | E77: #N/A | F77: #N/A | G77: #N/A | H77: 648 | I77: 1.1213 | J77: 2.531 | K77: 3.218 | L77: 4.5695 | M77: =IFERROR(C77,C78) -> 3.916 | N77: =IFERROR(D77,D78) -> 12.05 | O77: =IFERROR(E77,E78) -> 424.56 | P77: =IFERROR(F77,F78) -> 195.39 | Q77: =IFERROR(G77,G78) -> 394.94 | R77: =IFERROR(H77,H78) -> 648 | S77: =IFERROR(I77,I78) -> 1.1213 | T77: =IFERROR(J77,J78) -> 2.531 | U77: =IFERROR(K77,K78) -> 3.218 | V77: 1.0298
A78: 01/08/2025 | B78: 45.695 | C78: 3.919 | D78: 11.795 | E78: 424.56 | F78: 195.39 | G78: 394.94 | H78: 635.7 | I78: 1.1197 | J78: 2.524 | K78: 3.197 | L78: 4.5695 | M78: =IFERROR(C78,C79) -> 3.919 | N78: =IFERROR(D78,D79) -> 11.795 | O78: =IFERROR(E78,E79) -> 424.56 | P78: =IFERROR(F78,F79) -> 195.39 | Q78: =IFERROR(G78,G79) -> 394.94 | R78: =IFERROR(H78,H79) -> 635.7 | S78: =IFERROR(I78,I79) -> 1.1197 | T78: =IFERROR(J78,J79) -> 2.524 | U78: =IFERROR(K78,K79) -> 3.197 | V78: 1.0318
A79: 01/07/2025 | B79: 45.94 | C79: 3.923 | D79: 11.85 | E79: 422.37 | F79: 196.71 | G79: 394.36 | H79: 644.5 | I79: 1.1216 | J79: 2.4855 | K79: 3.141 | L79: 4.594 | M79: =IFERROR(C79,C80) -> 3.923 | N79: =IFERROR(D79,D80) -> 11.85 | O79: =IFERROR(E79,E80) -> 422.37 | P79: =IFERROR(F79,F80) -> 196.71 | Q79: =IFERROR(G79,G80) -> 394.36 | R79: =IFERROR(H79,H80) -> 644.5 | S79: =IFERROR(I79,I80) -> 1.1216 | T79: =IFERROR(J79,J80) -> 2.4855 | U79: =IFERROR(K79,K80) -> 3.141 | V79: 1.0339
A80: 01/06/2025 | B80: 45.5 | C80: 3.958 | D80: 12.015 | E80: 427.85 | F80: 197.96 | G80: 411.05 | H80: 634.6 | I80: 1.1313 | J80: 2.4475 | K80: 3.106 | L80: 4.55 | M80: =IFERROR(C80,C81) -> 3.958 | N80: =IFERROR(D80,D81) -> 12.015 | O80: =IFERROR(E80,E81) -> 427.85 | P80: =IFERROR(F80,F81) -> 197.96 | Q80: =IFERROR(G80,G81) -> 411.05 | R80: =IFERROR(H80,H81) -> 634.6 | S80: =IFERROR(I80,I81) -> 1.1313 | T80: =IFERROR(J80,J81) -> 2.4475 | U80: =IFERROR(K80,K81) -> 3.106 | V80: 1.039
...

Sheet base de datos final
A2: Santander | B2: Telefónica | C2: Repsol | D2: Microsoft | E2: Alphabet | F2: Tesla | G2: LVM | H2: us 30Y bond | I2: Germany 10y Bond | J2: España 10 y Bono | K2: EURUSD
A3: ='hoja intermedia'!L3 -> 6.416 | B3: ='hoja intermedia'!M3 -> 4.395 | C3: ='hoja intermedia'!N3 -> 10.72 | D3: ='hoja intermedia'!O3 -> 391.85 | E3: ='hoja intermedia'!P3 -> 163.85 | F3: ='hoja intermedia'!Q3 -> 284.95 | G3: ='hoja intermedia'!R3 -> 498.8 | H3: ='hoja intermedia'!S3 -> 1.1581 | ... K3: ='hoja intermedia'!V3 -> 1.1364
A4: ='hoja intermedia'!L4 -> 6.254 | B4: ='hoja intermedia'!M4 -> 4.359 | C4: ='hoja intermedia'!N4 -> 10.555 | D4: ='hoja intermedia'!O4 -> 387.3 | E4: ='hoja intermedia'!P4 -> 161.47 | F4: ='hoja intermedia'!Q4 -> 259.51 | G4: ='hoja intermedia'!R4 -> 499.7 | H4: ='hoja intermedia'!S4 -> 1.1519 | ... K4: ='hoja intermedia'!V4 -> 1.1388 | N4: Número títulos | O4: Inversión a precios de hoy
A5: ='hoja intermedia'!L5 -> 6.32 | B5: ='hoja intermedia'!M5 -> 4.355 | C5: ='hoja intermedia'!N5 -> 10.46 | D5: ='hoja intermedia'!O5 -> 374.39 | E5: ='hoja intermedia'!P5 -> 157.72 | F5: ='hoja intermedia'!Q5 -> 250.74 | G5: ='hoja intermedia'!R5 -> 500.3 | H5: ='hoja intermedia'!S5 -> 1.1416 | ... K5: ='hoja intermedia'!V5 -> 1.1313 | M5: Santander | N5: 20000 | O5: =N5*A3 -> 128320
A6: ='hoja intermedia'!L6 -> 6.053 | B6: ='hoja intermedia'!M6 -> 4.367 | C6: ='hoja intermedia'!N6 -> 10.325 | D6: ='hoja intermedia'!O6 -> 366.82 | E6: ='hoja intermedia'!P6 -> 153.9 | F6: ='hoja intermedia'!Q6 -> 237.97 | G6: ='hoja intermedia'!R6 -> 487.3 | H6: ='hoja intermedia'!S6 -> 1.1359 | ... K6: ='hoja intermedia'!V6 -> 1.142 | M6: Telefónica | N6: 30000 | O6: =N6*B3 -> 131850
A7: ='hoja intermedia'!L7 -> 5.942 | B7: ='hoja intermedia'!M7 -> 4.329 | C7: ='hoja intermedia'!N7 -> 10.325 | D7: ='hoja intermedia'!O7 -> 367.78 | E7: ='hoja intermedia'!P7 -> 153.36 | F7: ='hoja intermedia'!Q7 -> 241.37 | G7: ='hoja intermedia'!R7 -> 485.6 | H7: ='hoja intermedia'!S7 -> 1.1456 | ... K7: ='hoja intermedia'!V7 -> 1.1363 | M7: Repsol | N7: 12000 | O7: =N7*C3 -> 128640
A8: ='hoja intermedia'!L8 -> 6.025 | B8: ='hoja intermedia'!M8 -> 4.269 | C8: ='hoja intermedia'!N8 -> 10.15 | D8: ='hoja intermedia'!O8 -> 371.61 | E8: ='hoja intermedia'!P8 -> 155.5 | F8: ='hoja intermedia'!Q8 -> 241.55 | G8: ='hoja intermedia'!R8 -> 485.2 | H8: ='hoja intermedia'!S8 -> 1.1528 | ... K8: ='hoja intermedia'!V8 -> 1.1398 | M8: Microsoft | N8: 350 | O8: =N8*D3 -> 137147.5
A9: ='hoja intermedia'!L9 -> 6.006 | B9: ='hoja intermedia'!M9 -> 4.166 | C9: ='hoja intermedia'!N9 -> 9.98 | D9: ='hoja intermedia'!O9 -> 385.73 | E9: ='hoja intermedia'!P9 -> 158.68 | F9: ='hoja intermedia'!Q9 -> 254.11 | G9: ='hoja intermedia'!R9 -> 488.65 | H9: ='hoja intermedia'!S9 -> 1.1484 | ... K9: ='hoja intermedia'!V9 -> 1.1281 | M9: Alphabet | N9: 900 | O9: =N9*E3 -> 147465
A10: ='hoja intermedia'!L10 -> 5.798 | B10: ='hoja intermedia'!M10 -> 4.121 | C10: ='hoja intermedia'!N10 -> 9.934 | D10: ='hoja intermedia'!O10 -> 387.81 | E10: ='hoja intermedia'!P10 -> 161.47 | F10: ='hoja intermedia'!Q10 -> 252.35 | G10: ='hoja intermedia'!R10 -> 530.1 | H10: ='hoja intermedia'!S10 -> 1.145 | ... K10: ='hoja intermedia'!V10 -> 1.1349 | M10: Tesla | N10: 450 | O10: =N10*F3 -> 128227.5
A11: ='hoja intermedia'!L11 -> 5.588 | B11: ='hoja intermedia'!M11 -> 3.996 | C11: ='hoja intermedia'!N11 -> 9.592 | D11: ='hoja intermedia'!O11 -> 388.45 | E11: ='hoja intermedia'!P11 -> 159.4 | F11: ='hoja intermedia'!Q11 -> 252.31 | G11: ='hoja intermedia'!R11 -> 524.4 | H11: ='hoja intermedia'!S11 -> 1.1319 | ... K11: ='hoja intermedia'!V11 -> 1.136 | M11: LVM | N11: 300 | O11: =N11*G3 -> 149640
A12: ='hoja intermedia'!L12 -> 5.662 | B12: ='hoja intermedia'!M12 -> 3.95 | C12: ='hoja intermedia'!N12 -> 9.764 | D12: ='hoja intermedia'!O12 -> 381.35 | E12: ='hoja intermedia'!P12 -> 155.37 | F12: ='hoja intermedia'!Q12 -> 252.4 | G12: ='hoja intermedia'!R12 -> 524.2 | H12: ='hoja intermedia'!S12 -> 1.1388 | ... K12: ='hoja intermedia'!V12 -> 1.1197 | M12: us 30Y bond | N12: 120 | O12: =N12*H3*1000 -> 138972
A13: ='hoja intermedia'!L13 -> 5.365 | B13: ='hoja intermedia'!M13 -> 3.889 | C13: ='hoja intermedia'!N13 -> 9.58 | D13: ='hoja intermedia'!O13 -> 390.49 | E13: ='hoja intermedia'!P13 -> 161.06 | F13: ='hoja intermedia'!Q13 -> 272.2 | G13: ='hoja intermedia'!R13 -> 498.4 | H13: ='hoja intermedia'!S13 -> 1.1453 | ... K13: ='hoja intermedia'!V13 -> 1.0951 | M13: Germany 10y Bond | N13: 80 | O13: =N13*I3*1000 -> 195600
A14: ='hoja intermedia'!L14 -> 5.504 | B14: ='hoja intermedia'!M14 -> 4.081 | C14: ='hoja intermedia'!N14 -> 9.96 | D14: ='hoja intermedia'!O14 -> 354.56 | E14: ='hoja intermedia'!P14 -> 146.58 | F14: ='hoja intermedia'!Q14 -> 221.86 | G14: ='hoja intermedia'!R14 -> 519.8 | H14: ='hoja intermedia'!S14 -> 1.1575 | ... K14: ='hoja intermedia'!V14 -> 1.0956 | M14: España 10 y Bono | N14: 50 | O14: =N14*J3*1000 -> 157350
A15: ='hoja intermedia'!L15 -> 5.243 | B15: ='hoja intermedia'!M15 -> 4.1 | C15: ='hoja intermedia'!N15 -> 10.045 | D15: ='hoja intermedia'!O15 -> 357.86 | E15: ='hoja intermedia'!P15 -> 149.24 | F15: ='hoja intermedia'!Q15 -> 233.29 | G15: ='hoja intermedia'!R15 -> 507.6 | H15: ='hoja intermedia'!S15 -> 1.1763 | ... K15: ='hoja intermedia'!V15 -> 1.0904
A16: ='hoja intermedia'!L16 -> 5.494 | B16: ='hoja intermedia'!M16 -> 4.302 | C16: ='hoja intermedia'!N16 -> 10.785 | D16: ='hoja intermedia'!O16 -> 359.84 | E16: ='hoja intermedia'!P16 -> 147.74 | F16: ='hoja intermedia'!Q16 -> 239.43 | G16: ='hoja intermedia'!R16 -> 530 | H16: ='hoja intermedia'!S16 -> 1.2059 | ... K16: ='hoja intermedia'!V16 -> 1.0955 | O16: =SUM(O5:O14) -> 1443212
A17: ='hoja intermedia'!L17 -> 6.022 | B17: ='hoja intermedia'!M17 -> 4.472 | C17: ='hoja intermedia'!N17 -> 11.42 | D17: ='hoja intermedia'!O17 -> 373.11 | E17: ='hoja intermedia'!P17 -> 152.63 | F17: ='hoja intermedia'!Q17 -> 267.28 | G17: ='hoja intermedia'!R17 -> 542.9 | H17: ='hoja intermedia'!S17 -> 1.1941 | ... K17: ='hoja intermedia'!V17 -> 1.105
A18: ='hoja intermedia'!L18 -> 6.352 | B18: ='hoja intermedia'!M18 -> 4.374 | C18: ='hoja intermedia'!N18 -> 12.065 | D18: ='hoja intermedia'!O18 -> 382.14 | E18: ='hoja intermedia'!P18 -> 158.86 | F18: ='hoja intermedia'!Q18 -> 282.76 | G18: ='hoja intermedia'!R18 -> 575.2 | H18: ='hoja intermedia'!S18 -> 1.18 | ... K18: ='hoja intermedia'!V18 -> 1.0855
A19: ='hoja intermedia'!L19 -> 6.323 | B19: ='hoja intermedia'!M19 -> 4.418 | C19: ='hoja intermedia'!N19 -> 12.355 | D19: ='hoja intermedia'!O19 -> 382.19 | E19: ='hoja intermedia'!P19 -> 158.88 | F19: ='hoja intermedia'!Q19 -> 268.46 | G19: ='hoja intermedia'!R19 -> 575.1 | H19: ='hoja intermedia'!S19 -> 1.1859 | ... K19: ='hoja intermedia'!V19 -> 1.0793
A20: ='hoja intermedia'!L20 -> 6.196 | B20: ='hoja intermedia'!M20 -> 4.354 | C20: ='hoja intermedia'!N20 -> 12.3 | D20: ='hoja intermedia'!O20 -> 375.39 | E20: ='hoja intermedia'!P20 -> 156.23 | F20: ='hoja intermedia'!Q20 -> 259.16 | G20: ='hoja intermedia'!R20 -> 571.7 | H20: ='hoja intermedia'!S20 -> 1.1728 | ... K20: ='hoja intermedia'!V20 -> 1.0817
A21: ='hoja intermedia'!L21 -> 6.318 | B21: ='hoja intermedia'!M21 -> 4.322 | C21: ='hoja intermedia'!N21 -> 12.455 | D21: ='hoja intermedia'!O21 -> 378.8 | E21: ='hoja intermedia'!P21 -> 156.06 | F21: ='hoja intermedia'!Q21 -> 263.55 | G21: ='hoja intermedia'!R21 -> 587.1 | H21: ='hoja intermedia'!S21 -> 1.1709 | ... K21: ='hoja intermedia'!V21 -> 1.0827
A22: ='hoja intermedia'!L22 -> 6.452 | B22: ='hoja intermedia'!M22 -> 4.325 | C22: ='hoja intermedia'!N22 -> 12.515 | D22: ='hoja intermedia'!O22 -> 390.58 | E22: ='hoja intermedia'!P22 -> 164.08 | F22: ='hoja intermedia'!Q22 -> 273.13 | G22: ='hoja intermedia'!R22 -> 589.1 | H22: ='hoja intermedia'!S22 -> 1.1566 | ... K22: ='hoja intermedia'!V22 -> 1.0801
A23: ='hoja intermedia'!L23 -> 6.502 | B23: ='hoja intermedia'!M23 -> 4.303 | C23: ='hoja intermedia'!N23 -> 12.415 | D23: ='hoja intermedia'!O23 -> 389.97 | E23: ='hoja intermedia'!P23 -> 167.14 | F23: ='hoja intermedia'!Q23 -> 272.06 | G23: ='hoja intermedia'!R23 -> 594.5 | H23: ='hoja intermedia'!S23 -> 1.1616 | ... K23: ='hoja intermedia'!V23 -> 1.0752
A24: ='hoja intermedia'!L24 -> 6.619 | B24: ='hoja intermedia'!M24 -> 4.28 | C24: ='hoja intermedia'!N24 -> 12.15 | D24: ='hoja intermedia'!O24 -> 395.16 | E24: ='hoja intermedia'!P24 -> 172.79 | F24: ='hoja intermedia'!Q24 -> 288.14 | G24: ='hoja intermedia'!R24 -> 598.3 | H24: ='hoja intermedia'!S24 -> 1.1659 | ... K24: ='hoja intermedia'!V24 -> 1.0791
A25: ='hoja intermedia'!L25 -> 6.502 | B25: ='hoja intermedia'!M25 -> 4.255 | C25: ='hoja intermedia'!N25 -> 11.96 | D25: ='hoja intermedia'!O25 -> 393.08 | E25: ='hoja intermedia'!P25 -> 169.93 | F25: ='hoja intermedia'!Q25 -> 278.39 | G25: ='hoja intermedia'!R25 -> 596.3 | H25: ='hoja intermedia'!S25 -> 1.1641 | ... K25: ='hoja intermedia'!V25 -> 1.08
A26: ='hoja intermedia'!L26 -> 6.44 | B26: ='hoja intermedia'!M26 -> 4.339 | C26: ='hoja intermedia'!N26 -> 12.105 | D26: ='hoja intermedia'!O26 -> 391.26 | E26: ='hoja intermedia'!P26 -> 166.25 | F26: ='hoja intermedia'!Q26 -> 248.71 | G26: ='hoja intermedia'!R26 -> 602.5 | H26: ='hoja intermedia'!S26 -> 1.1738 | ... K26: ='hoja intermedia'!V26 -> 1.0814
A27: ='hoja intermedia'!L27 -> 6.4 | B27: ='hoja intermedia'!M27 -> 4.326 | C27: ='hoja intermedia'!N27 -> 12.065 | D27: ='hoja intermedia'!O27 -> 386.84 | E27: ='hoja intermedia'!P27 -> 165.05 | F27: ='hoja intermedia'!Q27 -> 236.26 | G27: ='hoja intermedia'!R27 -> 604.5 | H27: ='hoja intermedia'!S27 -> 1.1772 | ... K27: ='hoja intermedia'!V27 -> 1.0851
A28: ='hoja intermedia'!L28 -> 6.561 | B28: ='hoja intermedia'!M28 -> 4.333 | C28: ='hoja intermedia'!N28 -> 12.14 | D28: ='hoja intermedia'!O28 -> 387.82 | E28: ='hoja intermedia'!P28 -> 166.28 | F28: ='hoja intermedia'!Q28 -> 235.86 | G28: ='hoja intermedia'!R28 -> 610.6 | H28: ='hoja intermedia'!S28 -> 1.175 | ... K28: ='hoja intermedia'!V28 -> 1.0901
... A2641: ='hoja intermedia'!L2641 -> 6.1418 | B2641: ='hoja intermedia'!M2641 -> 11.664 | C2641: ='hoja intermedia'!N2641 -> 11.72 | D2641: ='hoja intermedia'!O2641 -> 46.76 | E2641: ='hoja intermedia'!P2641 -> 26.17 | F2641: ='hoja intermedia'!Q2641 -> 14.62 | G2641: ='hoja intermedia'!R2641 -> 130.85 | H2641: ='hoja intermedia'!S2641 -> 1.455 | ... K2641: ='hoja intermedia'!V2641 -> 1.2
